<?xml version="1.0" encoding="utf-8"?>
<!-- This URDF was automatically created by SolidWorks to URDF Exporter! Originally created by
Stephen Brawner (brawner@gmail.com) 
     Commit Version: 1.6.0-4-g7f85cfe  Build Version: 1.6.7995.38578
     For more information, please see http://wiki.ros.org/sw_urdf_exporter -->
<robot
  name="aliengoLerobot">


  <material name="black">
    <color rgba="0.0 0.0 0.0 1.0"/>
  </material>
  <material name="blue">
    <color rgba="0.0 0.0 0.8 1.0"/>
  </material>
  <material name="green">
    <color rgba="0.0 0.8 0.0 1.0"/>
  </material>
  <material name="grey">
    <color rgba="0.2 0.2 0.2 1.0"/>
  </material>
  <material name="silver">
    <color rgba="0.9137254901960784 0.9137254901960784 0.8470588235294118 1.0"/>
  </material>
  <material name="orange">
    <color rgba="1.0 0.4235294117647059 0.0392156862745098 1.0"/>
  </material>
  <material name="brown">
    <color rgba="0.8705882352941177 0.8117647058823529 0.7647058823529411 1.0"/>
  </material>
  <material name="red">
    <color rgba="0.8 0.0 0.0 1.0"/>
  </material>
  <material name="white">
    <color rgba="1.0 1.0 1.0 1.0"/>
  </material>

  <!-- Rotor related joint and link is only for demonstrate location. -->
  <!-- Actually, the rotor will rotate and the joint is not fixed. Reduction ratio should be considered. -->
  <!-- Debug mode will hung up the robot, use "true" or "false" to switch it. -->
  <!-- <xacro:if value="$(arg DEBUG)">
        <link name="world"/>
        <joint name="base_static_joint" type="fixed">
            <origin rpy="0 0 0" xyz="0 0 0"/>
            <parent link="world"/>
            <child link="base"/>
        </joint>
    </xacro:if>  -->
  <link name="base">
    <visual>
      <origin rpy="0 0 0" xyz="0 0 0"/>
      <geometry>
        <box size="0.001 0.001 0.001"/>
      </geometry>
    </visual>
  </link>
  <joint name="floating_base" type="fixed">
    <origin rpy="0 0 0" xyz="0 0 0"/>
    <parent link="base"/>
    <child link="trunk"/>
  </joint>
  <link name="trunk">
    <visual>
      <origin rpy="0 0 0" xyz="0 0 0"/>
      <geometry>
        <mesh filename="resources/robots/aliengo_description/meshes/trunk.dae" scale="1 1 1"/>
      </geometry>
      <material name="white"/>
    </visual>
    <collision>
      <origin rpy="0 0 0" xyz="0 0 0"/>
      <geometry>
        <box size="0.647 0.15 0.112"/>
      </geometry>
    </collision>
    <!-- <collision>
            <origin rpy="0 0 0" xyz="0 0 0"/>
            <geometry>
                <mesh filename="resources/robots/aliengo_description/meshes/trunk.dae" scale="1 1 1"/>
            </geometry>
        </collision> -->
    <inertial>
      <origin rpy="0 0 0" xyz="0.008811 0.003839 0.000273"/>
      <mass value="11.644"/>
      <inertia ixx="0.051944892" ixy="0.001703617" ixz="0.000235941" iyy="0.24693924" iyz="0.000119783" izz="0.270948307"/>
    </inertial>
  </link>
  <joint name="imu_joint" type="fixed">
    <parent link="trunk"/>
    <child link="imu_link"/>
    <origin rpy="0 0 0" xyz="0 0 0"/>
  </joint>
  <link name="imu_link">
    <inertial>
      <mass value="0.001"/>
      <origin rpy="0 0 0" xyz="0 0 0"/>
      <inertia ixx="0.0001" ixy="0" ixz="0" iyy="0.000001" iyz="0" izz="0.0001"/>
    </inertial>
    <visual>
      <origin rpy="0 0 0" xyz="0 0 0"/>
      <geometry>
        <box size="0.001 0.001 0.001"/>
      </geometry>
      <material name="red"/>
    </visual>
    <collision>
      <origin rpy="0 0 0" xyz="0 0 0"/>
      <geometry>
        <box size=".001 .001 .001"/>
      </geometry>
    </collision>
  </link>
  <!--aliengo-->
  <joint name="FR_hip_joint" type="revolute">
    <origin rpy="0 0 0" xyz="0.2407 -0.051 0"/>
    <parent link="trunk"/>
    <child link="FR_hip"/>
    <axis xyz="1 0 0"/>
    <dynamics damping="0" friction="0"/>
    <limit effort="35.278" lower="-1.2217304763960306" upper="1.2217304763960306" velocity="20"/>
  </joint>
  <joint name="FR_hip_rotor_joint" type="fixed">
    <origin rpy="0 0 0" xyz="0.139985 -0.051 0"/>
    <parent link="trunk"/>
    <child link="FR_hip_rotor"/>
  </joint>
  <link name="FR_hip">
    <visual>
      <origin rpy="3.141592653589793 0 0" xyz="0 0 0"/>
      <geometry>
        <mesh filename="resources/robots/aliengo_description/meshes/hip.dae" scale="1 1 1"/>
      </geometry>
      <material name="white"/>
    </visual>
    <collision>
      <origin rpy="1.5707963267948966 0 0" xyz="0 -0.083 0"/>
      <geometry>
        <cylinder length="0.0418" radius="0.046"/>
      </geometry>
    </collision>
    <inertial>
      <origin rpy="0 0 0" xyz="-0.022191 -0.015144 -1.5e-05"/>
      <mass value="1.993"/>
      <inertia ixx="0.002446735" ixy="0.00059805" ixz="1.945e-06" iyy="0.003925876" iyz="-1.284e-06" izz="0.004148145"/>
    </inertial>
  </link>
  <link name="FR_hip_rotor">
    <visual>
      <origin rpy="0 1.5707963267948966 0" xyz="0 0 0"/>
      <geometry>
        <cylinder length="0.02" radius="0.035"/>
      </geometry>
      <material name="green"/>
    </visual>
    <!-- <collision>
                <origin rpy="0 ${PI/2.0} 0" xyz="0 0 0"/>
                <geometry>
                    <cylinder length="0.02" radius="0.035"/>
                </geometry>
            </collision> -->
    <inertial>
      <origin rpy="0 0 0" xyz="0.0 0.0 0.0"/>
      <mass value="0.146"/>
      <inertia ixx="0.000138702" ixy="0.0" ixz="0.0" iyy="8.3352e-05" iyz="0.0" izz="8.3352e-05"/>
    </inertial>
  </link>
  <joint name="FR_thigh_joint" type="revolute">
    <origin rpy="0 0 0" xyz="0 -0.0868 0"/>
    <parent link="FR_hip"/>
    <child link="FR_thigh"/>
    <axis xyz="0 1 0"/>
    <dynamics damping="0" friction="0"/>
    <limit effort="35.278" lower="-0.524" upper="3.927" velocity="20"/>
  </joint>
  <joint name="FR_thigh_rotor_joint" type="fixed">
    <origin rpy="0 0 0" xyz="0.0 -0.0298 0"/>
    <parent link="FR_hip"/>
    <child link="FR_thigh_rotor"/>
  </joint>
  <link name="FR_thigh">
    <visual>
      <origin rpy="0 0 0" xyz="0 0 0"/>
      <geometry>
        <mesh filename="resources/robots/aliengo_description/meshes/thigh_mirror.dae" scale="1 1 1"/>
      </geometry>
      <material name="white"/>
    </visual>
    <collision>
      <origin rpy="0 1.5707963267948966 0" xyz="0 0 -0.125"/>
      <geometry>
        <box size="0.25 0.0374 0.043"/>
      </geometry>
    </collision>
    <inertial>
      <origin rpy="0 0 0" xyz="-0.005607 0.003877 -0.048199"/>
      <mass value="0.639"/>
      <inertia ixx="0.004173855" ixy="-1.0284e-05" ixz="-0.000318874" iyy="0.004343802" iyz="-0.000109233" izz="0.000340136"/>
    </inertial>
  </link>
  <link name="FR_thigh_rotor">
    <visual>
      <origin rpy="1.5707963267948966 0 0" xyz="0 0 0"/>
      <geometry>
        <cylinder length="0.02" radius="0.035"/>
      </geometry>
      <material name="green"/>
    </visual>
    <!-- <collision>
                <origin rpy="${PI/2.0} 0 0" xyz="0 0 0"/>
                <geometry>
                    <cylinder length="0.02" radius="0.035"/>
                </geometry>
            </collision> -->
    <inertial>
      <origin rpy="0 0 0" xyz="0.0 0.0 0.0"/>
      <mass value="0.146"/>
      <inertia ixx="8.3352e-05" ixy="0.0" ixz="0.0" iyy="0.000138702" iyz="0.0" izz="8.3352e-05"/>
    </inertial>
  </link>
  <joint name="FR_calf_joint" type="revolute">
    <origin rpy="0 0 0" xyz="0 0 -0.25"/>
    <parent link="FR_thigh"/>
    <child link="FR_calf"/>
    <axis xyz="0 1 0"/>
    <dynamics damping="0" friction="0"/>
    <limit effort="44.4" lower="-2.775073510670984" upper="-0.6457718232379019" velocity="15.89"/>
  </joint>
  <joint name="FR_calf_rotor_joint" type="fixed">
    <origin rpy="0 0 0" xyz="0.0 0.0997 0"/>
    <parent link="FR_thigh"/>
    <child link="FR_calf_rotor"/>
  </joint>
  <link name="FR_calf">
    <visual>
      <origin rpy="0 0 0" xyz="0 0 0"/>
      <geometry>
        <mesh filename="resources/robots/aliengo_description/meshes/calf.dae" scale="1 1 1"/>
      </geometry>
      <material name="white"/>
    </visual>
    <collision>
      <origin rpy="0 1.5707963267948966 0" xyz="0 0 -0.125"/>
      <geometry>
        <box size="0.25 0.0208 0.016"/>
      </geometry>
    </collision>
    <inertial>
      <origin rpy="0 0 0" xyz="0.002781 6.3e-05 -0.142518"/>
      <mass value="0.207"/>
      <inertia ixx="0.002129279" ixy="3.9e-08" ixz="5.757e-06" iyy="0.002141463" iyz="-5.16e-07" izz="3.7583e-05"/>
    </inertial>
  </link>
  <link name="FR_calf_rotor">
    <visual>
      <origin rpy="1.5707963267948966 0 0" xyz="0 0 0"/>
      <geometry>
        <cylinder length="0.02" radius="0.035"/>
      </geometry>
      <material name="green"/>
    </visual>
    <!-- <collision>
                <origin rpy="${PI/2.0} 0 0" xyz="0 0 0"/>
                <geometry>
                    <cylinder length="0.02" radius="0.035"/>
                </geometry>
            </collision> -->
    <inertial>
      <origin rpy="0 0 0" xyz="0.0 0.0 0.0"/>
      <mass value="0.132"/>
      <inertia ixx="0.000145463" ixy="0.0" ixz="0.0" iyy="0.000133031" iyz="0.0" izz="0.000145463"/>
    </inertial>
  </link>
  <joint name="FR_foot_fixed" type="fixed" dont_collapse="true">
    <origin rpy="0 0 0" xyz="0 0 -0.25"/>
    <parent link="FR_calf"/>
    <child link="FR_foot"/>
  </joint>
  <link name="FR_foot">
    <visual>
      <origin rpy="0 0 0" xyz="0 0 0"/>
      <geometry>
        <sphere radius="0.0165"/>
      </geometry>
      <material name="green"/>
    </visual>
    <collision>
      <origin rpy="0 0 0" xyz="0 0 0"/>
      <geometry>
        <sphere radius="0.0265"/>
      </geometry>
    </collision>
    <inertial>
      <mass value="0.06"/>
      <inertia ixx="1.6853999999999998e-05" ixy="0.0" ixz="0.0" iyy="1.6853999999999998e-05" iyz="0.0" izz="1.6853999999999998e-05"/>
    </inertial>
  </link>
  <joint name="FL_hip_joint" type="revolute">
    <origin rpy="0 0 0" xyz="0.2407 0.051 0"/>
    <parent link="trunk"/>
    <child link="FL_hip"/>
    <axis xyz="1 0 0"/>
    <dynamics damping="0" friction="0"/>
    <limit effort="35.278" lower="-1.2217304763960306" upper="1.2217304763960306" velocity="20"/>
  </joint>
  <joint name="FL_hip_rotor_joint" type="fixed">
    <origin rpy="0 0 0" xyz="0.139985 0.051 0"/>
    <parent link="trunk"/>
    <child link="FL_hip_rotor"/>
  </joint>
  <link name="FL_hip">
    <visual>
      <origin rpy="0 0 0" xyz="0 0 0"/>
      <geometry>
        <mesh filename="resources/robots/aliengo_description/meshes/hip.dae" scale="1 1 1"/>
      </geometry>
      <material name="white"/>
    </visual>
    <collision>
      <origin rpy="1.5707963267948966 0 0" xyz="0 0.083 0"/>
      <geometry>
        <cylinder length="0.0418" radius="0.046"/>
      </geometry>
    </collision>
    <inertial>
      <origin rpy="0 0 0" xyz="-0.022191 0.015144 -1.5e-05"/>
      <mass value="1.993"/>
      <inertia ixx="0.002446735" ixy="-0.00059805" ixz="1.945e-06" iyy="0.003925876" iyz="1.284e-06" izz="0.004148145"/>
    </inertial>
  </link>
  <link name="FL_hip_rotor">
    <visual>
      <origin rpy="0 1.5707963267948966 0" xyz="0 0 0"/>
      <geometry>
        <cylinder length="0.02" radius="0.035"/>
      </geometry>
      <material name="green"/>
    </visual>
    <!-- <collision>
                <origin rpy="0 ${PI/2.0} 0" xyz="0 0 0"/>
                <geometry>
                    <cylinder length="0.02" radius="0.035"/>
                </geometry>
            </collision> -->
    <inertial>
      <origin rpy="0 0 0" xyz="0.0 0.0 0.0"/>
      <mass value="0.146"/>
      <inertia ixx="0.000138702" ixy="0.0" ixz="0.0" iyy="8.3352e-05" iyz="0.0" izz="8.3352e-05"/>
    </inertial>
  </link>
  <joint name="FL_thigh_joint" type="revolute">
    <origin rpy="0 0 0" xyz="0 0.0868 0"/>
    <parent link="FL_hip"/>
    <child link="FL_thigh"/>
    <axis xyz="0 1 0"/>
    <dynamics damping="0" friction="0"/>
    <limit effort="35.278" lower="-0.524" upper="3.927" velocity="20"/>
  </joint>
  <joint name="FL_thigh_rotor_joint" type="fixed">
    <origin rpy="0 0 0" xyz="0.0 0.0298 0"/>
    <parent link="FL_hip"/>
    <child link="FL_thigh_rotor"/>
  </joint>
  <link name="FL_thigh">
    <visual>
      <origin rpy="0 0 0" xyz="0 0 0"/>
      <geometry>
        <mesh filename="resources/robots/aliengo_description/meshes/thigh.dae" scale="1 1 1"/>
      </geometry>
      <material name="white"/>
    </visual>
    <collision>
      <origin rpy="0 1.5707963267948966 0" xyz="0 0 -0.125"/>
      <geometry>
        <box size="0.25 0.0374 0.043"/>
      </geometry>
    </collision>
    <inertial>
      <origin rpy="0 0 0" xyz="-0.005607 -0.003877 -0.048199"/>
      <mass value="0.639"/>
      <inertia ixx="0.004173855" ixy="1.0284e-05" ixz="-0.000318874" iyy="0.004343802" iyz="0.000109233" izz="0.000340136"/>
    </inertial>
  </link>
  <link name="FL_thigh_rotor">
    <visual>
      <origin rpy="1.5707963267948966 0 0" xyz="0 0 0"/>
      <geometry>
        <cylinder length="0.02" radius="0.035"/>
      </geometry>
      <material name="green"/>
    </visual>
    <!-- <collision>
                <origin rpy="${PI/2.0} 0 0" xyz="0 0 0"/>
                <geometry>
                    <cylinder length="0.02" radius="0.035"/>
                </geometry>
            </collision> -->
    <inertial>
      <origin rpy="0 0 0" xyz="0.0 0.0 0.0"/>
      <mass value="0.146"/>
      <inertia ixx="8.3352e-05" ixy="0.0" ixz="0.0" iyy="0.000138702" iyz="0.0" izz="8.3352e-05"/>
    </inertial>
  </link>
  <joint name="FL_calf_joint" type="revolute">
    <origin rpy="0 0 0" xyz="0 0 -0.25"/>
    <parent link="FL_thigh"/>
    <child link="FL_calf"/>
    <axis xyz="0 1 0"/>
    <dynamics damping="0" friction="0"/>
    <limit effort="44.4" lower="-2.775073510670984" upper="-0.6457718232379019" velocity="15.89"/>
  </joint>
  <joint name="FL_calf_rotor_joint" type="fixed">
    <origin rpy="0 0 0" xyz="0.0 -0.0997 0"/>
    <parent link="FL_thigh"/>
    <child link="FL_calf_rotor"/>
  </joint>
  <link name="FL_calf">
    <visual>
      <origin rpy="0 0 0" xyz="0 0 0"/>
      <geometry>
        <mesh filename="resources/robots/aliengo_description/meshes/calf.dae" scale="1 1 1"/>
      </geometry>
      <material name="white"/>
    </visual>
    <collision>
      <origin rpy="0 1.5707963267948966 0" xyz="0 0 -0.125"/>
      <geometry>
        <box size="0.25 0.0208 0.016"/>
      </geometry>
    </collision>
    <inertial>
      <origin rpy="0 0 0" xyz="0.002781 6.3e-05 -0.142518"/>
      <mass value="0.207"/>
      <inertia ixx="0.002129279" ixy="3.9e-08" ixz="5.757e-06" iyy="0.002141463" iyz="-5.16e-07" izz="3.7583e-05"/>
    </inertial>
  </link>
  <link name="FL_calf_rotor">
    <visual>
      <origin rpy="1.5707963267948966 0 0" xyz="0 0 0"/>
      <geometry>
        <cylinder length="0.02" radius="0.035"/>
      </geometry>
      <material name="green"/>
    </visual>
    <!-- <collision>
                <origin rpy="${PI/2.0} 0 0" xyz="0 0 0"/>
                <geometry>
                    <cylinder length="0.02" radius="0.035"/>
                </geometry>
            </collision> -->
    <inertial>
      <origin rpy="0 0 0" xyz="0.0 0.0 0.0"/>
      <mass value="0.132"/>
      <inertia ixx="0.000145463" ixy="0.0" ixz="0.0" iyy="0.000133031" iyz="0.0" izz="0.000145463"/>
    </inertial>
  </link>
  <joint name="FL_foot_fixed" type="fixed" dont_collapse="true">
    <origin rpy="0 0 0" xyz="0 0 -0.25"/>
    <parent link="FL_calf"/>
    <child link="FL_foot"/>
  </joint>
  <link name="FL_foot">
    <visual>
      <origin rpy="0 0 0" xyz="0 0 0"/>
      <geometry>
        <sphere radius="0.0165"/>
      </geometry>
      <material name="green"/>
    </visual>
    <collision>
      <origin rpy="0 0 0" xyz="0 0 0"/>
      <geometry>
        <sphere radius="0.0265"/>
      </geometry>
    </collision>
    <inertial>
      <mass value="0.06"/>
      <inertia ixx="1.6853999999999998e-05" ixy="0.0" ixz="0.0" iyy="1.6853999999999998e-05" iyz="0.0" izz="1.6853999999999998e-05"/>
    </inertial>
  </link>
  <joint name="RR_hip_joint" type="revolute">
    <origin rpy="0 0 0" xyz="-0.2407 -0.051 0"/>
    <parent link="trunk"/>
    <child link="RR_hip"/>
    <axis xyz="1 0 0"/>
    <dynamics damping="0" friction="0"/>
    <limit effort="35.278" lower="-1.2217304763960306" upper="1.2217304763960306" velocity="20"/>
  </joint>
  <joint name="RR_hip_rotor_joint" type="fixed">
    <origin rpy="0 0 0" xyz="-0.139985 -0.051 0"/>
    <parent link="trunk"/>
    <child link="RR_hip_rotor"/>
  </joint>
  <link name="RR_hip">
    <visual>
      <origin rpy="3.141592653589793 3.141592653589793 0" xyz="0 0 0"/>
      <geometry>
        <mesh filename="resources/robots/aliengo_description/meshes/hip.dae" scale="1 1 1"/>
      </geometry>
      <material name="white"/>
    </visual>
    <collision>
      <origin rpy="1.5707963267948966 0 0" xyz="0 -0.083 0"/>
      <geometry>
        <cylinder length="0.0418" radius="0.046"/>
      </geometry>
    </collision>
    <inertial>
      <origin rpy="0 0 0" xyz="0.022191 -0.015144 -1.5e-05"/>
      <mass value="1.993"/>
      <inertia ixx="0.002446735" ixy="-0.00059805" ixz="-1.945e-06" iyy="0.003925876" iyz="-1.284e-06" izz="0.004148145"/>
    </inertial>
  </link>
  <link name="RR_hip_rotor">
    <visual>
      <origin rpy="0 1.5707963267948966 0" xyz="0 0 0"/>
      <geometry>
        <cylinder length="0.02" radius="0.035"/>
      </geometry>
      <material name="green"/>
    </visual>
    <!-- <collision>
                <origin rpy="0 ${PI/2.0} 0" xyz="0 0 0"/>
                <geometry>
                    <cylinder length="0.02" radius="0.035"/>
                </geometry>
            </collision> -->
    <inertial>
      <origin rpy="0 0 0" xyz="0.0 0.0 0.0"/>
      <mass value="0.146"/>
      <inertia ixx="0.000138702" ixy="0.0" ixz="0.0" iyy="8.3352e-05" iyz="0.0" izz="8.3352e-05"/>
    </inertial>
  </link>
  <joint name="RR_thigh_joint" type="revolute">
    <origin rpy="0 0 0" xyz="0 -0.0868 0"/>
    <parent link="RR_hip"/>
    <child link="RR_thigh"/>
    <axis xyz="0 1 0"/>
    <dynamics damping="0" friction="0"/>
    <limit effort="35.278" lower="-0.524" upper="3.927" velocity="20"/>
  </joint>
  <joint name="RR_thigh_rotor_joint" type="fixed">
    <origin rpy="0 0 0" xyz="0.0 -0.0298 0"/>
    <parent link="RR_hip"/>
    <child link="RR_thigh_rotor"/>
  </joint>
  <link name="RR_thigh">
    <visual>
      <origin rpy="0 0 0" xyz="0 0 0"/>
      <geometry>
        <mesh filename="resources/robots/aliengo_description/meshes/thigh_mirror.dae" scale="1 1 1"/>
      </geometry>
      <material name="white"/>
    </visual>
    <collision>
      <origin rpy="0 1.5707963267948966 0" xyz="0 0 -0.125"/>
      <geometry>
        <box size="0.25 0.0374 0.043"/>
      </geometry>
    </collision>
    <inertial>
      <origin rpy="0 0 0" xyz="-0.005607 0.003877 -0.048199"/>
      <mass value="0.639"/>
      <inertia ixx="0.004173855" ixy="-1.0284e-05" ixz="-0.000318874" iyy="0.004343802" iyz="-0.000109233" izz="0.000340136"/>
    </inertial>
  </link>
  <link name="RR_thigh_rotor">
    <visual>
      <origin rpy="1.5707963267948966 0 0" xyz="0 0 0"/>
      <geometry>
        <cylinder length="0.02" radius="0.035"/>
      </geometry>
      <material name="green"/>
    </visual>
    <!-- <collision>
                <origin rpy="${PI/2.0} 0 0" xyz="0 0 0"/>
                <geometry>
                    <cylinder length="0.02" radius="0.035"/>
                </geometry>
            </collision> -->
    <inertial>
      <origin rpy="0 0 0" xyz="0.0 0.0 0.0"/>
      <mass value="0.146"/>
      <inertia ixx="8.3352e-05" ixy="0.0" ixz="0.0" iyy="0.000138702" iyz="0.0" izz="8.3352e-05"/>
    </inertial>
  </link>
  <joint name="RR_calf_joint" type="revolute">
    <origin rpy="0 0 0" xyz="0 0 -0.25"/>
    <parent link="RR_thigh"/>
    <child link="RR_calf"/>
    <axis xyz="0 1 0"/>
    <dynamics damping="0" friction="0"/>
    <limit effort="44.4" lower="-2.775073510670984" upper="-0.6457718232379019" velocity="15.89"/>
  </joint>
  <joint name="RR_calf_rotor_joint" type="fixed">
    <origin rpy="0 0 0" xyz="0.0 0.0997 0"/>
    <parent link="RR_thigh"/>
    <child link="RR_calf_rotor"/>
  </joint>
  <link name="RR_calf">
    <visual>
      <origin rpy="0 0 0" xyz="0 0 0"/>
      <geometry>
        <mesh filename="resources/robots/aliengo_description/meshes/calf.dae" scale="1 1 1"/>
      </geometry>
      <material name="white"/>
    </visual>
    <collision>
      <origin rpy="0 1.5707963267948966 0" xyz="0 0 -0.125"/>
      <geometry>
        <box size="0.25 0.0208 0.016"/>
      </geometry>
    </collision>
    <inertial>
      <origin rpy="0 0 0" xyz="0.002781 6.3e-05 -0.142518"/>
      <mass value="0.207"/>
      <inertia ixx="0.002129279" ixy="3.9e-08" ixz="5.757e-06" iyy="0.002141463" iyz="-5.16e-07" izz="3.7583e-05"/>
    </inertial>
  </link>
  <link name="RR_calf_rotor">
    <visual>
      <origin rpy="1.5707963267948966 0 0" xyz="0 0 0"/>
      <geometry>
        <cylinder length="0.02" radius="0.035"/>
      </geometry>
      <material name="green"/>
    </visual>
    <!-- <collision>
                <origin rpy="${PI/2.0} 0 0" xyz="0 0 0"/>
                <geometry>
                    <cylinder length="0.02" radius="0.035"/>
                </geometry>
            </collision> -->
    <inertial>
      <origin rpy="0 0 0" xyz="0.0 0.0 0.0"/>
      <mass value="0.132"/>
      <inertia ixx="0.000145463" ixy="0.0" ixz="0.0" iyy="0.000133031" iyz="0.0" izz="0.000145463"/>
    </inertial>
  </link>
  <joint name="RR_foot_fixed" type="fixed" dont_collapse="true">
    <origin rpy="0 0 0" xyz="0 0 -0.25"/>
    <parent link="RR_calf"/>
    <child link="RR_foot"/>
  </joint>
  <link name="RR_foot">
    <visual>
      <origin rpy="0 0 0" xyz="0 0 0"/>
      <geometry>
        <sphere radius="0.0165"/>
      </geometry>
      <material name="green"/>
    </visual>
    <collision>
      <origin rpy="0 0 0" xyz="0 0 0"/>
      <geometry>
        <sphere radius="0.0265"/>
      </geometry>
    </collision>
    <inertial>
      <mass value="0.06"/>
      <inertia ixx="1.6853999999999998e-05" ixy="0.0" ixz="0.0" iyy="1.6853999999999998e-05" iyz="0.0" izz="1.6853999999999998e-05"/>
    </inertial>
  </link>
  <joint name="RL_hip_joint" type="revolute">
    <origin rpy="0 0 0" xyz="-0.2407 0.051 0"/>
    <parent link="trunk"/>
    <child link="RL_hip"/>
    <axis xyz="1 0 0"/>
    <dynamics damping="0" friction="0"/>
    <limit effort="35.278" lower="-1.2217304763960306" upper="1.2217304763960306" velocity="20"/>
  </joint>
  <joint name="RL_hip_rotor_joint" type="fixed">
    <origin rpy="0 0 0" xyz="-0.139985 0.051 0"/>
    <parent link="trunk"/>
    <child link="RL_hip_rotor"/>
  </joint>
  <link name="RL_hip">
    <visual>
      <origin rpy="0 3.141592653589793 0" xyz="0 0 0"/>
      <geometry>
        <mesh filename="resources/robots/aliengo_description/meshes/hip.dae" scale="1 1 1"/>
      </geometry>
      <material name="white"/>
    </visual>
    <collision>
      <origin rpy="1.5707963267948966 0 0" xyz="0 0.083 0"/>
      <geometry>
        <cylinder length="0.0418" radius="0.046"/>
      </geometry>
    </collision>
    <inertial>
      <origin rpy="0 0 0" xyz="0.022191 0.015144 -1.5e-05"/>
      <mass value="1.993"/>
      <inertia ixx="0.002446735" ixy="0.00059805" ixz="-1.945e-06" iyy="0.003925876" iyz="1.284e-06" izz="0.004148145"/>
    </inertial>
  </link>
  <link name="RL_hip_rotor">
    <visual>
      <origin rpy="0 1.5707963267948966 0" xyz="0 0 0"/>
      <geometry>
        <cylinder length="0.02" radius="0.035"/>
      </geometry>
      <material name="green"/>
    </visual>
    <!-- <collision>
                <origin rpy="0 ${PI/2.0} 0" xyz="0 0 0"/>
                <geometry>
                    <cylinder length="0.02" radius="0.035"/>
                </geometry>
            </collision> -->
    <inertial>
      <origin rpy="0 0 0" xyz="0.0 0.0 0.0"/>
      <mass value="0.146"/>
      <inertia ixx="0.000138702" ixy="0.0" ixz="0.0" iyy="8.3352e-05" iyz="0.0" izz="8.3352e-05"/>
    </inertial>
  </link>
  <joint name="RL_thigh_joint" type="revolute">
    <origin rpy="0 0 0" xyz="0 0.0868 0"/>
    <parent link="RL_hip"/>
    <child link="RL_thigh"/>
    <axis xyz="0 1 0"/>
    <dynamics damping="0" friction="0"/>
    <limit effort="35.278"  lower="-0.524" upper="3.927" velocity="20"/>
  </joint>
  <joint name="RL_thigh_rotor_joint" type="fixed">
    <origin rpy="0 0 0" xyz="0.0 0.0298 0"/>
    <parent link="RL_hip"/>
    <child link="RL_thigh_rotor"/>
  </joint>
  <link name="RL_thigh">
    <visual>
      <origin rpy="0 0 0" xyz="0 0 0"/>
      <geometry>
        <mesh filename="resources/robots/aliengo_description/meshes/thigh.dae" scale="1 1 1"/>
      </geometry>
      <material name="white"/>
    </visual>
    <collision>
      <origin rpy="0 1.5707963267948966 0" xyz="0 0 -0.125"/>
      <geometry>
        <box size="0.25 0.0374 0.043"/>
      </geometry>
    </collision>
    <inertial>
      <origin rpy="0 0 0" xyz="-0.005607 -0.003877 -0.048199"/>
      <mass value="0.639"/>
      <inertia ixx="0.004173855" ixy="1.0284e-05" ixz="-0.000318874" iyy="0.004343802" iyz="0.000109233" izz="0.000340136"/>
    </inertial>
  </link>
  <link name="RL_thigh_rotor">
    <visual>
      <origin rpy="1.5707963267948966 0 0" xyz="0 0 0"/>
      <geometry>
        <cylinder length="0.02" radius="0.035"/>
      </geometry>
      <material name="green"/>
    </visual>
    <!-- <collision>
                <origin rpy="${PI/2.0} 0 0" xyz="0 0 0"/>
                <geometry>
                    <cylinder length="0.02" radius="0.035"/>
                </geometry>
            </collision> -->
    <inertial>
      <origin rpy="0 0 0" xyz="0.0 0.0 0.0"/>
      <mass value="0.146"/>
      <inertia ixx="8.3352e-05" ixy="0.0" ixz="0.0" iyy="0.000138702" iyz="0.0" izz="8.3352e-05"/>
    </inertial>
  </link>
  <joint name="RL_calf_joint" type="revolute">
    <origin rpy="0 0 0" xyz="0 0 -0.25"/>
    <parent link="RL_thigh"/>
    <child link="RL_calf"/>
    <axis xyz="0 1 0"/>
    <dynamics damping="0" friction="0"/>
    <limit effort="44.4" lower="-2.775073510670984" upper="-0.6457718232379019" velocity="15.89"/>
  </joint>
  <joint name="RL_calf_rotor_joint" type="fixed">
    <origin rpy="0 0 0" xyz="0.0 -0.0997 0"/>
    <parent link="RL_thigh"/>
    <child link="RL_calf_rotor"/>
  </joint>
  <link name="RL_calf">
    <visual>
      <origin rpy="0 0 0" xyz="0 0 0"/>
      <geometry>
        <mesh filename="resources/robots/aliengo_description/meshes/calf.dae" scale="1 1 1"/>
      </geometry>
      <material name="white"/>
    </visual>
    <collision>
      <origin rpy="0 1.5707963267948966 0" xyz="0 0 -0.125"/>
      <geometry>
        <box size="0.25 0.0208 0.016"/>
      </geometry>
    </collision>
    <inertial>
      <origin rpy="0 0 0" xyz="0.002781 6.3e-05 -0.142518"/>
      <mass value="0.207"/>
      <inertia ixx="0.002129279" ixy="3.9e-08" ixz="5.757e-06" iyy="0.002141463" iyz="-5.16e-07" izz="3.7583e-05"/>
    </inertial>
  </link>
  <link name="RL_calf_rotor">
    <visual>
      <origin rpy="1.5707963267948966 0 0" xyz="0 0 0"/>
      <geometry>
        <cylinder length="0.02" radius="0.035"/>
      </geometry>
      <material name="green"/>
    </visual>
    <!-- <collision>
                <origin rpy="${PI/2.0} 0 0" xyz="0 0 0"/>
                <geometry>
                    <cylinder length="0.02" radius="0.035"/>
                </geometry>
            </collision> -->
    <inertial>
      <origin rpy="0 0 0" xyz="0.0 0.0 0.0"/>
      <mass value="0.132"/>
      <inertia ixx="0.000145463" ixy="0.0" ixz="0.0" iyy="0.000133031" iyz="0.0" izz="0.000145463"/>
    </inertial>
  </link>
  <joint name="RL_foot_fixed" type="fixed" dont_collapse="true">
    <origin rpy="0 0 0" xyz="0 0 -0.25"/>
    <parent link="RL_calf"/>
    <child link="RL_foot"/>
  </joint>
  <link name="RL_foot">
    <visual>
      <origin rpy="0 0 0" xyz="0 0 0"/>
      <geometry>
        <sphere radius="0.0165"/>
      </geometry>
      <material name="green"/>
    </visual>
    <collision>
      <origin rpy="0 0 0" xyz="0 0 0"/>
      <geometry>
        <sphere radius="0.0265"/>
      </geometry>
    </collision>
    <inertial>
      <mass value="0.06"/>
      <inertia ixx="1.6853999999999998e-05" ixy="0.0" ixz="0.0" iyy="1.6853999999999998e-05" iyz="0.0" izz="1.6853999999999998e-05"/>
    </inertial>
  </link>


  <!--机械臂-->
  <joint name="trunk_arm_joint" type="fixed">
      <origin rpy="0.0 0.0 0.0" xyz="0.085 0 0.094" />
      <parent link="base" />
      <child link="base_arm_link" />
  </joint>

  <link
      name="base_arm_link">
      <inertial>
          <origin
              xyz="-3.764e-5 0.00006519 0.03037877"
              rpy="0 0 0" />
          <mass
              value="0.428" />
          <inertia
              ixx="0.00060728"
              ixy="3.437e-7"
              ixz="9.790e-7"
              iyy="0.00060832"
              iyz="-1.696e-6"
              izz="1.917e-4" />
      </inertial>
      <visual>
          <origin
              xyz="0 0 0"
              rpy="0 0 0" />
          <geometry>
              <mesh
                  filename="resources/robots/go2_arx5/arx5_meshes/base_link_new.stl" />
          </geometry>
          <material
              name="">
              <color
                  rgba="0.75294 0.75294 0.75294 1" />
          </material>
      </visual>
      <!-- <collision>
      <origin
          xyz="0 0 0.0255"
          rpy="0 0 0" />
      <geometry>
          <cylinder length="0.0255" radius="0.0325" />
      </geometry>
  </collision> -->
  </link>
  <link
      name="link1">
      <inertial>
          <origin
              xyz="0.00571213 0.0002547 0.01750661"
              rpy="0 0 0" />
          <mass
              value="0.064" />
          <inertia
              ixx="0.00009409"
              ixy="1.205e-6"
              ixz="-0.00001468"
              iyy="0.00005072"
              iyz="1.397e-6"
              izz="7.180e-5" />
      </inertial>
      <visual>
          <origin
              xyz="0 0 0"
              rpy="0 0 0" />
          <geometry>
              <mesh
                  filename="resources/robots/go2_arx5/arx5_meshes/link1_new.stl" />
          </geometry>
          <material
              name="">
              <color
                  rgba="0.752941176470588 0.752941176470588 0.752941176470588 1" />
          </material>
      </visual>
  </link>
  <joint
      name="joint1"
      type="revolute">
      <dynamics damping="0.0" friction="0.0" />
      <origin
          xyz="0 0 0.0603"
          rpy="0 0 0" />
      <parent
          link="base_arm_link" />
      <child
          link="link1" />
      <axis
          xyz="0 0 1" />
      <limit
          lower="-3.14159265359"
          upper="3.14159265359"
          effort="30"
          velocity="10" />
  </joint>
  <link
      name="link2">
      <inertial>
          <origin
              xyz="-0.13225701 0.00072373 4.274e-5"
              rpy="0 0 0" />
          <mass
              value="1.165" />
          <inertia
              ixx="0.00057063"
              ixy="0.00011251"
              ixz="0.00001979"
              iyy="0.03669927"
              iyz="1.203e-8"
              izz="0.03683489" />
      </inertial>
      <visual>
          <origin
              xyz="0 0 0"
              rpy="0 0 0" />
          <geometry>
              <mesh
                  filename="resources/robots/go2_arx5/arx5_meshes/link2_new.stl" />
          </geometry>
          <material
              name="">
              <color
                  rgba="0.752941176470588 0.752941176470588 0.752941176470588 1" />
          </material>
      </visual>
      <collision>
          <origin
              xyz="-0.135 0 0"
              rpy="0 1.5707963267948966 0" />
          <geometry>
              <cylinder length="0.155" radius="0.025" />
          </geometry>
      </collision>
  </link>
  <joint
      name="joint2"
      type="revolute">
      <dynamics damping="0.0" friction="0.0" />
      <origin
          xyz="0.02 0 0.0402"
          rpy="0 0 0" />
      <parent
          link="link1" />
      <child
          link="link2" />
      <axis
          xyz="0 1 0" />
      <limit
          lower="0"
          upper="3.66519"
          effort="30"
          velocity="10" />
  </joint>
  <link
      name="link3">
      <inertial>
          <origin
              xyz="0.19096098 0.00069065 -0.05342172"
              rpy="0 0 0" />
          <mass
              value="0.546" />
          <inertia
              ixx="0.00178249"
              ixy="-0.00003986"
              ixz="0.00571"
              iyy="0.02486615"
              iyz="1.346e-5"
              izz="0.02329476" />
      </inertial>
      <visual>
          <origin
              xyz="0 0 0"
              rpy="0 0 0" />
          <geometry>
              <mesh
                  filename="resources/robots/go2_arx5/arx5_meshes/link3_new.stl" />
          </geometry>
          <material
              name="">
              <color
                  rgba="0.752941176470588 0.752941176470588 0.752941176470588 1" />
          </material>
      </visual>
      <collision>
          <origin
              xyz="0.15 0 -0.055"
              rpy="0 1.5707963267948966 0" />
          <geometry>
              <cylinder length="0.15" radius="0.02" />
          </geometry>
      </collision>
  </link>
  <joint
      name="joint3"
      type="revolute">
      <dynamics damping="0.0" friction="0.0" />
      <origin
          xyz="-0.264 0 0"
          rpy="-3.1416 0 0" />
      <parent
          link="link2" />
      <child
          link="link3" />
      <axis
          xyz="0 1 0" />
      <limit
          lower="0"
          upper="3.14159265359"
          effort="30"
          velocity="10" />
  </joint>
  <link
      name="link4">
      <inertial>
          <origin
              xyz="0.03092317 0.0066107 -0.03138504"
              rpy="0 0 0" />
          <mass
              value="0.100" />
          <inertia
              ixx="0.00017832"
              ixy="0.00001697"
              ixz="0.0000776"
              iyy="0.00021182"
              iyz="-0.00001779"
              izz="0.00011328" />
      </inertial>
      <visual>
          <origin
              xyz="0 0 0"
              rpy="0 0 0" />
          <geometry>
              <mesh
                  filename="resources/robots/go2_arx5/arx5_meshes/link4_new.stl" />
          </geometry>
          <material
              name="">
              <color
                  rgba="0.898039215686275 0.917647058823529 0.929411764705882 1" />
          </material>
      </visual>
      <collision>
          <origin
              xyz="0.06575 -0.001 -0.02"
              rpy="0 0 0" />
          <geometry>
              <cylinder length="0.05" radius="0.025" />
          </geometry>
      </collision>
  </link>
  <joint
      name="joint4"
      type="revolute">
      <dynamics damping="0.0" friction="0.0" />
      <origin
          xyz="0.245 0 -0.056"
          rpy="0 0 0" />
      <parent
          link="link3" />
      <child
          link="link4" />
      <axis
          xyz="0 1 0" />
      <limit
          lower="-1.57079632679 "
          upper="1.57079632679 "
          effort="30"
          velocity="10" />
  </joint>
  <link
      name="link5">
      <inertial>
          <origin
              xyz="0.0040681 0.00000885 0.05120675"
              rpy="0 0 0" />
          <mass
              value="0.655" />
          <inertia
              ixx="0.00254972"
              ixy="2.600e-7"
              ixz="-0.00021534"
              iyy="0.00255018"
              iyz="-5.980e-7"
              izz="0.00026961" />
      </inertial>
      <visual>
          <origin
              xyz="0 0 0"
              rpy="0 0 0" />
          <geometry>
              <mesh
                  filename="resources/robots/go2_arx5/arx5_meshes/link5_new.stl" />
          </geometry>
          <material
              name="">
              <color
                  rgba="0.752941176470588 0.752941176470588 0.752941176470588 1" />
          </material>
      </visual>
      <!-- <collision>
          <origin
              xyz="0.055 0.00 0.083"
              rpy="0 1.5707963267948966 0" />
          <geometry>
              <cylinder length="0.025" radius="0.02" />
          </geometry>
      </collision> -->
  </link>
  <joint
      name="joint5"
      type="revolute">
      <dynamics damping="0.0" friction="0.0" />
      <origin
          xyz="0.06575 -0.001 -0.0825"
          rpy="0 0 0" />
      <parent
          link="link4" />
      <child
          link="link5" />
      <axis
          xyz="0 0 1" />
      <limit
          lower="-1.57079632679 "
          upper="1.57079632679 "
          effort="30"
          velocity="10" />
  </joint>
  <link
      name="link6">
      <inertial>
          <origin
              xyz="0.05435277 -0.00734005 0.01881196"
              rpy="0 0 0" />
          <mass value="0.902" />
          <inertia
              ixx="0.00229822"
              ixy="1.254e-4"
              ixz="-0.00037442"
              iyy="0.00596005"
              iyz="0.00054471"
              izz="0.00530799" />
      </inertial>
      <visual>
          <origin
              xyz="0 0 0"
              rpy="0.0 0 0" />
          <geometry>
              <mesh
                  filename="resources/robots/go2_arx5/arx5_meshes/link6_truncated.stl" />
          </geometry>
          <material
              name="">
              <color
                  rgba="0.898039215686275 0.917647058823529 0.929411764705882 1" />
          </material>
      </visual>
      <collision>
          <origin
              xyz="0 0 0"
              rpy="1.57079632679 0 0" />
          <geometry>
              <mesh
                  filename="resources/robots/go2_arx5/arx5_meshes/link6_truncated.stl" />
          </geometry>
          <material
              name="">
              <color
                  rgba="0.898039215686275 0.917647058823529 0.929411764705882 1" />
          </material>
      </collision>
      <!-- go pro -->
      <visual>
          <origin xyz="0.016 -0.02 0.085" rpy="0 0 0" />
          <geometry>
              <box size="0.034 0.071 0.055" />
          </geometry>
      </visual>
      <collision>
          <origin xyz="0.016 -0.02 0.085" rpy="0 0 0" />
          <geometry>
              <box size="0.034 0.071 0.055" />
          </geometry>
      </collision>
      <!-- left finger -->
      <visual>
          <origin xyz="0.072 -0.002 0" rpy="0 1.57079632679 1.57079632679" />
          <geometry>
              <mesh
                  filename="resources/robots/go2_arx5/arx5_meshes/one_piece_wide_grasp_finray_finger.obj" />
          </geometry>
      </visual>
      <collision>
          <origin xyz="0.072 -0.002 0" rpy="0 1.57079632679 0.0" />
          <geometry>
              <mesh
                  filename="resources/robots/go2_arx5/arx5_meshes/collider.obj" />
          </geometry>
      </collision>
      <!-- right finger -->
      <visual>
          <origin xyz="0.072 0.002 0" rpy="0 -1.57079632679 1.57079632679" />
          <geometry>
              <mesh
                  filename="resources/robots/go2_arx5/arx5_meshes/one_piece_wide_grasp_finray_finger.obj" />
          </geometry>
      </visual>
      <collision>
          <origin xyz="0.072 0.002 0" rpy="3.14159265359 -1.57079632679 0.0" />
          <geometry>
              <mesh
                  filename="resources/robots/go2_arx5/arx5_meshes/collider.obj" />
          </geometry>
      </collision>
  </link>
  <joint
      name="joint6"
      type="revolute">
      <dynamics damping="0.0" friction="0.0" />
      <origin
          xyz="0.02845 0 0.0825"
          rpy="-3.1416 0 0" />
      <parent
          link="link5" />
      <child
          link="link6" />
      <axis
          xyz="1 0 0" />
      <limit
          lower="-1.57079632679"
          upper="1.57079632679"
          effort="30"
          velocity="10" />
  </joint>
  <link name="end_effector">
      <visual>
          <geometry>
              <sphere radius="0.01" />
          </geometry>
      </visual>
      <inertial>
          <mass value="0.0" />
      </inertial>
  </link>
  <joint name="ee_gripper" type="fixed" dont_collapse="true">
      <origin
          xyz="0.22 0 0"
          rpy="-1.57079632679 0 -1.57079632679" />
      <parent
          link="link6" />
      <child
          link="end_effector" />
  </joint>
  <joint name="FR_foot_target_joint"
      type="fixed" dont_collapse="true">
      <origin xyz="0.35 -0.20 0" rpy="0 0 0" />
      <parent link="base" />
      <child link="FR_foot_target" />
  </joint>
  <link name="FR_foot_target">
  </link>
  <joint name="FL_foot_target_joint"
      type="fixed" dont_collapse="true">
      <origin xyz="0.35 0.20 0" rpy="0 0 0" />
      <parent link="base" />
      <child link="FL_foot_target" />
  </joint>
  <link name="FL_foot_target">
  </link>
  <joint name="RR_foot_target_joint"
      type="fixed" dont_collapse="true">
      <origin xyz="-0.20 -0.20 0" rpy="0 0 0" />
      <parent link="base" />
      <child link="RR_foot_target" />
  </joint>
  <link name="RR_foot_target">
  </link>
  <joint name="RL_foot_target_joint"
      type="fixed" dont_collapse="true">
      <origin xyz="-0.20 0.20 0" rpy="0 0 0" />
      <parent link="base" />
      <child link="RL_foot_target" />
  </joint>
  <link name="RL_foot_target">
  </link>

</robot>