<?xml version="1.0" ?>
<!-- =================================================================================== -->
<!-- |    This document was autogenerated by xacro from robot.xacro                    | -->
<!-- |    EDITING THIS FILE BY HAND IS NOT RECOMMENDED                                 | -->
<!-- =================================================================================== -->
<robot name="aliengoPiper">
  <material name="black">
    <color rgba="0.0 0.0 0.0 1.0"/>
  </material>
  <material name="blue">
    <color rgba="0.0 0.0 0.8 1.0"/>
  </material>
  <material name="green">
    <color rgba="0.0 0.8 0.0 1.0"/>
  </material>
  <material name="grey">
    <color rgba="0.2 0.2 0.2 1.0"/>
  </material>
  <material name="silver">
    <color rgba="0.9137254901960784 0.9137254901960784 0.8470588235294118 1.0"/>
  </material>
  <material name="orange">
    <color rgba="1.0 0.4235294117647059 0.0392156862745098 1.0"/>
  </material>
  <material name="brown">
    <color rgba="0.8705882352941177 0.8117647058823529 0.7647058823529411 1.0"/>
  </material>
  <material name="red">
    <color rgba="0.8 0.0 0.0 1.0"/>
  </material>
  <material name="white">
    <color rgba="1.0 1.0 1.0 1.0"/>
  </material>
  <link name="base">
    <visual>
      <origin rpy="0 0 0" xyz="0 0 0"/>
      <geometry>
        <box size="0.001 0.001 0.001"/>
      </geometry>
    </visual>
  </link>  
  <joint name="floating_base" type="fixed">
    <origin rpy="0 0 0" xyz="0 0 0"/>
    <parent link="base"/>
    <child link="trunk"/>
  </joint>
  <link name="trunk">
    <visual>
      <origin rpy="0 0 0" xyz="0 0 0"/>
      <geometry>
        <mesh filename="resources/robots/aliengo_description/meshes/trunk.dae" scale="1 1 1"/>
      </geometry>
      <material name="brown"/>
    </visual>
    <collision>
      <origin rpy="0 0 0" xyz="0 0 0"/>
      <geometry>
        <box size="0.647 0.15 0.112"/>
      </geometry>
    </collision>
    <inertial>
      <origin rpy="0 0 0" xyz="0.008811 0.003839 0.000273"/>
      <mass value="11.644"/>
      <inertia ixx="0.051944892" ixy="0.001703617" ixz="0.000235941" iyy="0.24693924" iyz="0.000119783" izz="0.270948307"/>
    </inertial>
  </link>
  <joint name="imu_joint" type="fixed">
    <parent link="trunk"/>
    <child link="imu_link"/>
    <origin rpy="0 0 0" xyz="0 0 0"/>
  </joint>
  <link name="imu_link">
    <inertial>
      <mass value="0.001"/>
      <origin rpy="0 0 0" xyz="0 0 0"/>
      <inertia ixx="0.0001" ixy="0" ixz="0" iyy="0.000001" iyz="0" izz="0.0001"/>
    </inertial>
    <visual>
      <origin rpy="0 0 0" xyz="0 0 0"/>
      <geometry>
        <box size="0.001 0.001 0.001"/>
      </geometry>
      <material name="red"/>
    </visual>
    <collision>
      <origin rpy="0 0 0" xyz="0 0 0"/>
      <geometry>
        <box size=".001 .001 .001"/>
      </geometry>
    </collision>
  </link>
   --&gt;

    
  <!--Piper机械臂-->
  <joint name="trunk_arm_joint" type="fixed">
      <origin rpy="0.0 0.0 0.0" xyz="0.00 0.0 0.07" />
      <parent link="base" />
      <child link="base_arm_link" />
  </joint>
  <link
    name="base_arm_link">
    <inertial>
      <origin
        xyz="-0.00979274765955341 1.82905827587138E-06 0.0410100126360189"
        rpy="0 0 0" />
      <mass
        value="0.162548567403693" />
      <inertia
        ixx="0.000226596924525071"
        ixy="-7.33972270153965E-08"
        ixz="2.13249977802622E-06"
        iyy="0.000269444772561524"
        iyz="8.15169009611054E-09"
        izz="0.000222318258878636" />
    </inertial>
    <visual>
      <origin
        xyz="0 0 0"
        rpy="0 0 0" />
      <geometry>
        <mesh
          filename="resources/robots/piper_description/meshes/base_link.dae" />
      </geometry>
      <material
        name="">
        <color
          rgba="0.792156862745098 0.819607843137255 0.933333333333333 1" />
      </material>
    </visual>
    <collision>
      <origin
        xyz="0 0 0"
        rpy="0 0 0" />
      <geometry>
        <mesh
          filename="resources/robots/piper_description/meshes/base_link.STL" />
      </geometry>
    </collision>
  </link>
  <link
    name="link1">
    <inertial>
      <origin
        xyz="0.00131676031927024 0.000310288842008612 -0.00922874512303437"
        rpy="0 0 0" />
      <mass
        value="0.0978679932242825" /> <!--value="0.0978679932242825"-->
      <inertia
        ixx="7.76684558296782E-05"
        ixy="1.09084650459924E-07"
        ixz="-1.9748053243241E-06"
        iyy="9.24967780161547E-05"
        iyz="9.91284646834582E-07"
        izz="8.24589062407807E-05" />
    </inertial>
    <visual>
      <origin
        xyz="0 0 0"
        rpy="0 0 0" />
      <geometry>
        <mesh
          filename="resources/robots/piper_description/meshes/link1.dae" />
      </geometry>
      <material
        name="">
        <color
          rgba="0.792156862745098 0.819607843137255 0.933333333333333 1" />
      </material>
    </visual>
    <collision>
      <origin
        xyz="0 0 0"
        rpy="0 0 0" />
      <geometry>
        <mesh
          filename="resources/robots/piper_description/meshes/link1.STL" />
      </geometry>
    </collision>
  </link>
  <joint
    name="joint1"
    type="revolute">
    <origin
      xyz="0 0 0.123"
      rpy="0 0 -1.5708" />
    <parent
      link="base_arm_link" />
    <child
      link="link1" />
    <axis
      xyz="0 0 1" />
    <limit
      lower="-2.618"
      upper="2.618"
      effort="100"
      velocity="3" />
  </joint>
  <link
    name="link2">
    <inertial>
      <origin
        xyz="0.148793602378802 -0.00242026983944119 0.00175154638467948"
        rpy="0 0 0" />
      <mass
        value="0.290888938633388" />  <!--value="0.290888938633388"-->
      <inertia
        ixx="0.000148959640166183"
        ixy="-7.37750384371657E-05"
        ixz="-9.68688405196236E-07"
        iyy="0.00172800946632652"
        iyz="-1.09692225564224E-06"
        izz="0.0017754628344594" />
    </inertial>
    <visual>
      <origin
        xyz="0 0 0"
        rpy="0 0 0" />
      <geometry>
        <mesh
          filename="resources/robots/piper_description/meshes/link2.dae" />
      </geometry>
      <material
        name="">
        <color
          rgba="0.792156862745098 0.819607843137255 0.933333333333333 1" />
      </material>
    </visual>
    <collision>
      <origin
        xyz="0 0 0"
        rpy="0 0 0" />
      <geometry>
        <mesh
          filename="resources/robots/piper_description/meshes/link2.STL" />
      </geometry>
    </collision>
  </link>
  <joint
    name="joint2"
    type="revolute">
    <origin
      xyz="0 0 0"
      rpy="1.5708 0 -1.5708" />
    <parent
      link="link1" />
    <child
      link="link2" />
    <axis
      xyz="0 0 1" />
    <limit
      lower="0"
      upper="3.14"
      effort="100"
      velocity="3" />
  </joint>
  <link
    name="link3">
    <inertial>
      <origin
        xyz="-0.0996835215213704 0.0349477226691318 0.000508025815507312"
        rpy="0 0 0" />
      <mass
        value="0.290847697793211" />  <!--value="0.290847697793211"-->
      <inertia
        ixx="0.000107879011637167"
        ixy="2.92669521203626E-05"
        ixz="6.825922326238E-07"
        iyy="0.000214751671792086"
        iyz="-7.78469047878196E-07"
        izz="0.000241923439340319" />
    </inertial>
    <visual>
      <origin
        xyz="0 0 0"
        rpy="0 0 0" />
      <geometry>
        <mesh
          filename="resources/robots/piper_description/meshes/link3.dae" />
      </geometry>
      <material
        name="">
        <color
          rgba="0.792156862745098 0.819607843137255 0.933333333333333 1" />
      </material>
    </visual>
    <collision>
      <origin
        xyz="0 0 0"
        rpy="0 0 0" />
      <geometry>
        <mesh
          filename="resources/robots/piper_description/meshes/link3.STL" />
      </geometry>
    </collision>
  </link>
  <joint
    name="joint3"
    type="revolute">
    <origin
      xyz="0.28358 0.028726 0"
      rpy="0 0 0.10095" />
    <parent
      link="link2" />
    <child
      link="link3" />
    <axis
      xyz="0 0 1" />
    <limit
      lower="-2.697"
      upper="0"
      effort="100"
      velocity="3" />
  </joint>
  <link
    name="link4">
    <inertial>
      <origin
        xyz="0.000276464622387979 -0.00102803669324875 -0.00472830700561663"
        rpy="0 0 0" />
      <mass
        value="0.127087348341362" />   <!--value="0.127087348341362"-->
      <inertia
        ixx="3.82011730423416E-05"
        ixy="-4.92358350897513E-08"
        ixz="4.89589432973119E-08"
        iyy="4.87048555222578E-05"
        iyz="6.70802942500512E-08"
        izz="4.10592077565559E-05" />
    </inertial>
    <visual>
      <origin
        xyz="0 0 0"
        rpy="0 0 0" />
      <geometry>
        <mesh
          filename="resources/robots/piper_description/meshes/link4.dae" />
      </geometry>
      <material
        name="">
        <color
          rgba="0.792156862745098 0.819607843137255 0.933333333333333 1" />
      </material>
    </visual>
    <collision>
      <origin
        xyz="0 0 0"
        rpy="0 0 0" />
      <geometry>
        <mesh
          filename="resources/robots/piper_description/meshes/link4.STL" />
      </geometry>
    </collision>
  </link>
  <joint
    name="joint4"
    type="revolute">
    <origin
      xyz="-0.24221 0.068514 0"
      rpy="-1.5708 0 1.3826" />
    <parent
      link="link3" />
    <child
      link="link4" />
    <axis
      xyz="0 0 1" />
    <limit
      lower="-1.832"
      upper="1.832"
      effort="100"
      velocity="3" />
  </joint>
  <link
    name="link5">
    <inertial>
      <origin
        xyz="8.82262433516967E-05 0.0566829014808256 -0.00196119720482461"
        rpy="0 0 0" />
      <mass
        value="0.144711242639457" />  <!--value="0.144711242639457"-->
      <inertia
        ixx="4.39644313662493E-05"
        ixy="-3.59259686444846E-08"
        ixz="-1.89747741386183E-08"
        iyy="5.63173920951307E-05"
        iyz="-2.1540716689785E-07"
        izz="4.88713664675268E-05" />
    </inertial>
    <visual>
      <origin
        xyz="0 0 0"
        rpy="0 0 0" />
      <geometry>
        <mesh
          filename="resources/robots/piper_description/meshes/link5.dae" />
      </geometry>
      <material
        name="">
        <color
          rgba="0.792156862745098 0.819607843137255 0.933333333333333 1" />
      </material>
    </visual>
    <collision>
      <origin
        xyz="0 0 0"
        rpy="0 0 0" />
      <geometry>
        <mesh
          filename="resources/robots/piper_description/meshes/link5.STL" />
      </geometry>
    </collision>
  </link>
  <joint
    name="joint5"
    type="revolute">
    <origin
      xyz="0 0 0"
      rpy="1.5708 0 0" />
    <parent
      link="link4" />
    <child
      link="link5" />
    <axis
      xyz="0 0 1" />
    <limit
      lower="-1.22"
      upper="1.22"
      effort="100"
      velocity="3" />
  </joint>
  <link
    name="link6">
    <inertial>
      <origin
        xyz="0.00103120214523473 0.0121761387587524 0.0315480874960164"
        rpy="0 0 0" />
      <mass
        value="0.195187143240719" />   <!--value="0.195187143240719"-->
      <inertia
        ixx="6.43790256535539E-05"
        ixy="-1.2366166157046E-06"
        ixz="1.97664606328472E-07"
        iyy="0.000126146396374301"
        iyz="2.41157078516408E-06"
        izz="0.000154087076816444" />
    </inertial>
    <visual>
      <origin
        xyz="0 0 0"
        rpy="0 0 0" />
      <geometry>
        <mesh
          filename="resources/robots/piper_description/meshes/link6.dae" />
      </geometry>
      <material
        name="">
        <color
          rgba="0.792156862745098 0.819607843137255 0.933333333333333 1" />
      </material>
    </visual>
    <collision>
      <origin
        xyz="0 0 0"
        rpy="0 0 0" />
      <geometry>
        <mesh
          filename="resources/robots/piper_description/meshes/link6.STL" />
      </geometry>
    </collision>
  </link>
  <joint
    name="joint6"
    type="revolute">
    <origin
      xyz="0 0.091 0.0014165"
      rpy="-1.5708 -1.5708 0" />
    <parent
      link="link5" />
    <child
      link="link6" />
    <axis
      xyz="0 0 1" />
    <limit
      lower="-3.14"
      upper="3.14"
      effort="100"
      velocity="3" />
  </joint>
  <link
      name="link7">
      <inertial>
          <origin
              xyz="0.05435277 -0.00734005 0.01881196"
              rpy="0 0 0" />
          <mass value="0.902" />   <!--value="0.902"-->
          <inertia
              ixx="0.00229822"
              ixy="1.254e-4"
              ixz="-0.00037442"
              iyy="0.00596005"
              iyz="0.00054471"
              izz="0.00530799" />
      </inertial>
      <!-- go pro -->
      <visual>
          <origin xyz="0.016 -0.02 0.085" rpy="0 0 0" />
          <geometry>
              <box size="0.034 0.071 0.055" />
          </geometry>
      </visual>
      <collision>
          <origin xyz="0.016 -0.02 0.085" rpy="0 0 0" />
          <geometry>
              <box size="0.034 0.071 0.055" />
          </geometry>
      </collision>
      <!-- left finger -->
      <visual>
          <origin xyz="0.072 -0.002 0" rpy="0 1.57079632679 1.57079632679" />
          <geometry>
              <mesh
                  filename="resources/robots/go2_arx5/arx5_meshes/one_piece_wide_grasp_finray_finger.obj" />
          </geometry>
      </visual>
      <collision>
          <origin xyz="0.072 -0.002 0" rpy="0 1.57079632679 0.0" />
          <geometry>
              <mesh
                  filename="resources/robots/go2_arx5/arx5_meshes/collider.obj" />
          </geometry>
      </collision>
      <!-- right finger -->
      <visual>
          <origin xyz="0.072 0.002 0" rpy="0 -1.57079632679 1.57079632679" />
          <geometry>
              <mesh
                  filename="resources/robots/go2_arx5/arx5_meshes/one_piece_wide_grasp_finray_finger.obj" />
          </geometry>
      </visual>
      <collision>
          <origin xyz="0.072 0.002 0" rpy="3.14159265359 -1.57079632679 0.0" />
          <geometry>
              <mesh
                  filename="resources/robots/go2_arx5/arx5_meshes/collider.obj" />
          </geometry>
      </collision>
  </link>
  <joint
      name="joint7"
      type="fixed">
      <dynamics damping="0.0" friction="0.0" />
      <origin
          xyz="0.0 0 0.0"
          rpy="-1.57 -1.57 0" />
      <parent
          link="link6" />
      <child
          link="link7" />
      <axis
          xyz="1 0 0" />
      <limit
          lower="-1.57079632679"
          upper="1.57079632679"
          effort="30"
          velocity="10" />
  </joint>
  <link name="end_effector">
      <visual>
          <geometry>
              <sphere radius="0.01" />
          </geometry>
      </visual>
      <inertial>
          <mass value="0.0" />
      </inertial>
  </link>
  <joint name="ee_gripper" type="fixed" dont_collapse="true">
      <origin
          xyz="0.22 0 0"
          rpy="-1.57079632679 0 -1.57079632679" />
      <parent
          link="link7" />
      <child
          link="end_effector" />
  </joint>
  
  <!--aliengo-->
  <joint name="FR_hip_joint" type="revolute">
    <origin rpy="0 0 0" xyz="0.2407 -0.051 0"/>
    <parent link="trunk"/>
    <child link="FR_hip"/>
    <axis xyz="1 0 0"/>
    <dynamics damping="0" friction="0"/>
    <limit effort="35.278" lower="-1.2217304763960306" upper="1.2217304763960306" velocity="20"/>
  </joint>
  <joint name="FR_hip_rotor_joint" type="fixed">
    <origin rpy="0 0 0" xyz="0.139985 -0.051 0"/>
    <parent link="trunk"/>
    <child link="FR_hip_rotor"/>
  </joint>
  <link name="FR_hip">
    <visual>
      <origin rpy="3.141592653589793 0 0" xyz="0 0 0"/>
      <geometry>
        <mesh filename="resources/robots/aliengo_description/meshes/hip.dae" scale="1 1 1"/>
      </geometry>
      <material name="brown"/>
    </visual>
    <collision>
      <origin rpy="1.5707963267948966 0 0" xyz="0 -0.083 0"/>
      <geometry>
        <cylinder length="0.0418" radius="0.046"/>
      </geometry>
    </collision>
    <inertial>
      <origin rpy="0 0 0" xyz="-0.022191 -0.015144 -1.5e-05"/>
      <mass value="1.993"/>
      <inertia ixx="0.002446735" ixy="0.00059805" ixz="1.945e-06" iyy="0.003925876" iyz="-1.284e-06" izz="0.004148145"/>
    </inertial>
  </link>
  <link name="FR_hip_rotor">
    <visual>
      <origin rpy="0 1.5707963267948966 0" xyz="0 0 0"/>
      <geometry>
        <cylinder length="0.02" radius="0.035"/>
      </geometry>
      <material name="green"/>
    </visual>
    <!-- <collision>
                <origin rpy="0 ${PI/2.0} 0" xyz="0 0 0"/>
                <geometry>
                    <cylinder length="0.02" radius="0.035"/>
                </geometry>
            </collision> -->
    <inertial>
      <origin rpy="0 0 0" xyz="0.0 0.0 0.0"/>
      <mass value="0.146"/>
      <inertia ixx="0.000138702" ixy="0.0" ixz="0.0" iyy="8.3352e-05" iyz="0.0" izz="8.3352e-05"/>
    </inertial>
  </link>
  <joint name="FR_thigh_joint" type="revolute">
    <origin rpy="0 0 0" xyz="0 -0.0868 0"/>
    <parent link="FR_hip"/>
    <child link="FR_thigh"/>
    <axis xyz="0 1 0"/>
    <dynamics damping="0" friction="0"/>
    <limit effort="35.278" lower="-0.524" upper="3.927" velocity="20"/>
  </joint>
  <joint name="FR_thigh_rotor_joint" type="fixed">
    <origin rpy="0 0 0" xyz="0.0 -0.0298 0"/>
    <parent link="FR_hip"/>
    <child link="FR_thigh_rotor"/>
  </joint>
  <link name="FR_thigh">
    <visual>
      <origin rpy="0 0 0" xyz="0 0 0"/>
      <geometry>
        <mesh filename="resources/robots/aliengo_description/meshes/thigh_mirror.dae" scale="1 1 1"/>
      </geometry>
      <material name="brown"/>
    </visual>
    <collision>
      <origin rpy="0 1.5707963267948966 0" xyz="0 0 -0.125"/>
      <geometry>
        <box size="0.25 0.0374 0.043"/>
      </geometry>
    </collision>
    <inertial>
      <origin rpy="0 0 0" xyz="-0.005607 0.003877 -0.048199"/>
      <mass value="0.639"/>
      <inertia ixx="0.004173855" ixy="-1.0284e-05" ixz="-0.000318874" iyy="0.004343802" iyz="-0.000109233" izz="0.000340136"/>
    </inertial>
  </link>
  <link name="FR_thigh_rotor">
    <visual>
      <origin rpy="1.5707963267948966 0 0" xyz="0 0 0"/>
      <geometry>
        <cylinder length="0.02" radius="0.035"/>
      </geometry>
      <material name="green"/>
    </visual>
    <!-- <collision>
                <origin rpy="${PI/2.0} 0 0" xyz="0 0 0"/>
                <geometry>
                    <cylinder length="0.02" radius="0.035"/>
                </geometry>
            </collision> -->
    <inertial>
      <origin rpy="0 0 0" xyz="0.0 0.0 0.0"/>
      <mass value="0.146"/>
      <inertia ixx="8.3352e-05" ixy="0.0" ixz="0.0" iyy="0.000138702" iyz="0.0" izz="8.3352e-05"/>
    </inertial>
  </link>
  <joint name="FR_calf_joint" type="revolute">
    <origin rpy="0 0 0" xyz="0 0 -0.25"/>
    <parent link="FR_thigh"/>
    <child link="FR_calf"/>
    <axis xyz="0 1 0"/>
    <dynamics damping="0" friction="0"/>
    <limit effort="44.4" lower="-2.775073510670984" upper="-0.6457718232379019" velocity="15.89"/>
  </joint>
  <joint name="FR_calf_rotor_joint" type="fixed">
    <origin rpy="0 0 0" xyz="0.0 0.0997 0"/>
    <parent link="FR_thigh"/>
    <child link="FR_calf_rotor"/>
  </joint>
  <link name="FR_calf">
    <visual>
      <origin rpy="0 0 0" xyz="0 0 0"/>
      <geometry>
        <mesh filename="resources/robots/aliengo_description/meshes/calf.dae" scale="1 1 1"/>
      </geometry>
      <material name="brown"/>
    </visual>
    <collision>
      <origin rpy="0 1.5707963267948966 0" xyz="0 0 -0.125"/>
      <geometry>
        <box size="0.25 0.0208 0.016"/>
      </geometry>
    </collision>
    <inertial>
      <origin rpy="0 0 0" xyz="0.002781 6.3e-05 -0.142518"/>
      <mass value="0.207"/>
      <inertia ixx="0.002129279" ixy="3.9e-08" ixz="5.757e-06" iyy="0.002141463" iyz="-5.16e-07" izz="3.7583e-05"/>
    </inertial>
  </link>
  <link name="FR_calf_rotor">
    <visual>
      <origin rpy="1.5707963267948966 0 0" xyz="0 0 0"/>
      <geometry>
        <cylinder length="0.02" radius="0.035"/>
      </geometry>
      <material name="green"/>
    </visual>
    <!-- <collision>
                <origin rpy="${PI/2.0} 0 0" xyz="0 0 0"/>
                <geometry>
                    <cylinder length="0.02" radius="0.035"/>
                </geometry>
            </collision> -->
    <inertial>
      <origin rpy="0 0 0" xyz="0.0 0.0 0.0"/>
      <mass value="0.132"/>
      <inertia ixx="0.000145463" ixy="0.0" ixz="0.0" iyy="0.000133031" iyz="0.0" izz="0.000145463"/>
    </inertial>
  </link>
  <joint name="FR_foot_fixed" type="fixed" dont_collapse="true">
    <origin rpy="0 0 0" xyz="0 0 -0.25"/>
    <parent link="FR_calf"/>
    <child link="FR_foot"/>
  </joint>
  <link name="FR_foot">
    <visual>
      <origin rpy="0 0 0" xyz="0 0 0"/>
      <geometry>
        <sphere radius="0.0165"/>
      </geometry>
      <material name="green"/>
    </visual>
    <collision>
      <origin rpy="0 0 0" xyz="0 0 0"/>
      <geometry>
        <sphere radius="0.0265"/>
      </geometry>
    </collision>
    <inertial>
      <mass value="0.06"/>
      <inertia ixx="1.6853999999999998e-05" ixy="0.0" ixz="0.0" iyy="1.6853999999999998e-05" iyz="0.0" izz="1.6853999999999998e-05"/>
    </inertial>
  </link>
  <transmission name="FR_hip_tran">
    <type>transmission_interface/SimpleTransmission</type>
    <joint name="FR_hip_joint">
      <hardwareInterface>hardware_interface/EffortJointInterface</hardwareInterface>
    </joint>
    <actuator name="FR_hip_motor">
      <hardwareInterface>hardware_interface/EffortJointInterface</hardwareInterface>
      <mechanicalReduction>1</mechanicalReduction>
    </actuator>
  </transmission>
  <transmission name="FR_thigh_tran">
    <type>transmission_interface/SimpleTransmission</type>
    <joint name="FR_thigh_joint">
      <hardwareInterface>hardware_interface/EffortJointInterface</hardwareInterface>
    </joint>
    <actuator name="FR_thigh_motor">
      <hardwareInterface>hardware_interface/EffortJointInterface</hardwareInterface>
      <mechanicalReduction>1</mechanicalReduction>
    </actuator>
  </transmission>
  <transmission name="FR_calf_tran">
    <type>transmission_interface/SimpleTransmission</type>
    <joint name="FR_calf_joint">
      <hardwareInterface>hardware_interface/EffortJointInterface</hardwareInterface>
    </joint>
    <actuator name="FR_calf_motor">
      <hardwareInterface>hardware_interface/EffortJointInterface</hardwareInterface>
      <mechanicalReduction>1</mechanicalReduction>
    </actuator>
  </transmission>
  <joint name="FL_hip_joint" type="revolute">
    <origin rpy="0 0 0" xyz="0.2407 0.051 0"/>
    <parent link="trunk"/>
    <child link="FL_hip"/>
    <axis xyz="1 0 0"/>
    <dynamics damping="0" friction="0"/>
    <limit effort="35.278" lower="-1.2217304763960306" upper="1.2217304763960306" velocity="20"/>
  </joint>
  <joint name="FL_hip_rotor_joint" type="fixed">
    <origin rpy="0 0 0" xyz="0.139985 0.051 0"/>
    <parent link="trunk"/>
    <child link="FL_hip_rotor"/>
  </joint>
  <link name="FL_hip">
    <visual>
      <origin rpy="0 0 0" xyz="0 0 0"/>
      <geometry>
        <mesh filename="resources/robots/aliengo_description/meshes/hip.dae" scale="1 1 1"/>
      </geometry>
      <material name="brown"/>
    </visual>
    <collision>
      <origin rpy="1.5707963267948966 0 0" xyz="0 0.083 0"/>
      <geometry>
        <cylinder length="0.0418" radius="0.046"/>
      </geometry>
    </collision>
    <inertial>
      <origin rpy="0 0 0" xyz="-0.022191 0.015144 -1.5e-05"/>
      <mass value="1.993"/>
      <inertia ixx="0.002446735" ixy="-0.00059805" ixz="1.945e-06" iyy="0.003925876" iyz="1.284e-06" izz="0.004148145"/>
    </inertial>
  </link>
  <link name="FL_hip_rotor">
    <visual>
      <origin rpy="0 1.5707963267948966 0" xyz="0 0 0"/>
      <geometry>
        <cylinder length="0.02" radius="0.035"/>
      </geometry>
      <material name="green"/>
    </visual>
    <!-- <collision>
                <origin rpy="0 ${PI/2.0} 0" xyz="0 0 0"/>
                <geometry>
                    <cylinder length="0.02" radius="0.035"/>
                </geometry>
            </collision> -->
    <inertial>
      <origin rpy="0 0 0" xyz="0.0 0.0 0.0"/>
      <mass value="0.146"/>
      <inertia ixx="0.000138702" ixy="0.0" ixz="0.0" iyy="8.3352e-05" iyz="0.0" izz="8.3352e-05"/>
    </inertial>
  </link>
  <joint name="FL_thigh_joint" type="revolute">
    <origin rpy="0 0 0" xyz="0 0.0868 0"/>
    <parent link="FL_hip"/>
    <child link="FL_thigh"/>
    <axis xyz="0 1 0"/>
    <dynamics damping="0" friction="0"/>
    <limit effort="35.278" lower="-0.524" upper="3.927" velocity="20"/>
  </joint>
  <joint name="FL_thigh_rotor_joint" type="fixed">
    <origin rpy="0 0 0" xyz="0.0 0.0298 0"/>
    <parent link="FL_hip"/>
    <child link="FL_thigh_rotor"/>
  </joint>
  <link name="FL_thigh">
    <visual>
      <origin rpy="0 0 0" xyz="0 0 0"/>
      <geometry>
        <mesh filename="resources/robots/aliengo_description/meshes/thigh.dae" scale="1 1 1"/>
      </geometry>
      <material name="brown"/>
    </visual>
    <collision>
      <origin rpy="0 1.5707963267948966 0" xyz="0 0 -0.125"/>
      <geometry>
        <box size="0.25 0.0374 0.043"/>
      </geometry>
    </collision>
    <inertial>
      <origin rpy="0 0 0" xyz="-0.005607 -0.003877 -0.048199"/>
      <mass value="0.639"/>
      <inertia ixx="0.004173855" ixy="1.0284e-05" ixz="-0.000318874" iyy="0.004343802" iyz="0.000109233" izz="0.000340136"/>
    </inertial>
  </link>
  <link name="FL_thigh_rotor">
    <visual>
      <origin rpy="1.5707963267948966 0 0" xyz="0 0 0"/>
      <geometry>
        <cylinder length="0.02" radius="0.035"/>
      </geometry>
      <material name="green"/>
    </visual>
    <!-- <collision>
                <origin rpy="${PI/2.0} 0 0" xyz="0 0 0"/>
                <geometry>
                    <cylinder length="0.02" radius="0.035"/>
                </geometry>
            </collision> -->
    <inertial>
      <origin rpy="0 0 0" xyz="0.0 0.0 0.0"/>
      <mass value="0.146"/>
      <inertia ixx="8.3352e-05" ixy="0.0" ixz="0.0" iyy="0.000138702" iyz="0.0" izz="8.3352e-05"/>
    </inertial>
  </link>
  <joint name="FL_calf_joint" type="revolute">
    <origin rpy="0 0 0" xyz="0 0 -0.25"/>
    <parent link="FL_thigh"/>
    <child link="FL_calf"/>
    <axis xyz="0 1 0"/>
    <dynamics damping="0" friction="0"/>
    <limit effort="44.4" lower="-2.775073510670984" upper="-0.6457718232379019" velocity="15.89"/>
  </joint>
  <joint name="FL_calf_rotor_joint" type="fixed">
    <origin rpy="0 0 0" xyz="0.0 -0.0997 0"/>
    <parent link="FL_thigh"/>
    <child link="FL_calf_rotor"/>
  </joint>
  <link name="FL_calf">
    <visual>
      <origin rpy="0 0 0" xyz="0 0 0"/>
      <geometry>
        <mesh filename="resources/robots/aliengo_description/meshes/calf.dae" scale="1 1 1"/>
      </geometry>
      <material name="brown"/>
    </visual>
    <collision>
      <origin rpy="0 1.5707963267948966 0" xyz="0 0 -0.125"/>
      <geometry>
        <box size="0.25 0.0208 0.016"/>
      </geometry>
    </collision>
    <inertial>
      <origin rpy="0 0 0" xyz="0.002781 6.3e-05 -0.142518"/>
      <mass value="0.207"/>
      <inertia ixx="0.002129279" ixy="3.9e-08" ixz="5.757e-06" iyy="0.002141463" iyz="-5.16e-07" izz="3.7583e-05"/>
    </inertial>
  </link>
  <link name="FL_calf_rotor">
    <visual>
      <origin rpy="1.5707963267948966 0 0" xyz="0 0 0"/>
      <geometry>
        <cylinder length="0.02" radius="0.035"/>
      </geometry>
      <material name="green"/>
    </visual>
    <!-- <collision>
                <origin rpy="${PI/2.0} 0 0" xyz="0 0 0"/>
                <geometry>
                    <cylinder length="0.02" radius="0.035"/>
                </geometry>
            </collision> -->
    <inertial>
      <origin rpy="0 0 0" xyz="0.0 0.0 0.0"/>
      <mass value="0.132"/>
      <inertia ixx="0.000145463" ixy="0.0" ixz="0.0" iyy="0.000133031" iyz="0.0" izz="0.000145463"/>
    </inertial>
  </link>
  <joint name="FL_foot_fixed" type="fixed" dont_collapse="true">
    <origin rpy="0 0 0" xyz="0 0 -0.25"/>
    <parent link="FL_calf"/>
    <child link="FL_foot"/>
  </joint>
  <link name="FL_foot">
    <visual>
      <origin rpy="0 0 0" xyz="0 0 0"/>
      <geometry>
        <sphere radius="0.0165"/>
      </geometry>
      <material name="green"/>
    </visual>
    <collision>
      <origin rpy="0 0 0" xyz="0 0 0"/>
      <geometry>
        <sphere radius="0.0265"/>
      </geometry>
    </collision>
    <inertial>
      <mass value="0.06"/>
      <inertia ixx="1.6853999999999998e-05" ixy="0.0" ixz="0.0" iyy="1.6853999999999998e-05" iyz="0.0" izz="1.6853999999999998e-05"/>
    </inertial>
  </link>
  <transmission name="FL_hip_tran">
    <type>transmission_interface/SimpleTransmission</type>
    <joint name="FL_hip_joint">
      <hardwareInterface>hardware_interface/EffortJointInterface</hardwareInterface>
    </joint>
    <actuator name="FL_hip_motor">
      <hardwareInterface>hardware_interface/EffortJointInterface</hardwareInterface>
      <mechanicalReduction>1</mechanicalReduction>
    </actuator>
  </transmission>
  <transmission name="FL_thigh_tran">
    <type>transmission_interface/SimpleTransmission</type>
    <joint name="FL_thigh_joint">
      <hardwareInterface>hardware_interface/EffortJointInterface</hardwareInterface>
    </joint>
    <actuator name="FL_thigh_motor">
      <hardwareInterface>hardware_interface/EffortJointInterface</hardwareInterface>
      <mechanicalReduction>1</mechanicalReduction>
    </actuator>
  </transmission>
  <transmission name="FL_calf_tran">
    <type>transmission_interface/SimpleTransmission</type>
    <joint name="FL_calf_joint">
      <hardwareInterface>hardware_interface/EffortJointInterface</hardwareInterface>
    </joint>
    <actuator name="FL_calf_motor">
      <hardwareInterface>hardware_interface/EffortJointInterface</hardwareInterface>
      <mechanicalReduction>1</mechanicalReduction>
    </actuator>
  </transmission>
  <joint name="RR_hip_joint" type="revolute">
    <origin rpy="0 0 0" xyz="-0.2407 -0.051 0"/>
    <parent link="trunk"/>
    <child link="RR_hip"/>
    <axis xyz="1 0 0"/>
    <dynamics damping="0" friction="0"/>
    <limit effort="35.278" lower="-1.2217304763960306" upper="1.2217304763960306" velocity="20"/>
  </joint>
  <joint name="RR_hip_rotor_joint" type="fixed">
    <origin rpy="0 0 0" xyz="-0.139985 -0.051 0"/>
    <parent link="trunk"/>
    <child link="RR_hip_rotor"/>
  </joint>
  <link name="RR_hip">
    <visual>
      <origin rpy="3.141592653589793 3.141592653589793 0" xyz="0 0 0"/>
      <geometry>
        <mesh filename="resources/robots/aliengo_description/meshes/hip.dae" scale="1 1 1"/>
      </geometry>
      <material name="brown"/>
    </visual>
    <collision>
      <origin rpy="1.5707963267948966 0 0" xyz="0 -0.083 0"/>
      <geometry>
        <cylinder length="0.0418" radius="0.046"/>
      </geometry>
    </collision>
    <inertial>
      <origin rpy="0 0 0" xyz="0.022191 -0.015144 -1.5e-05"/>
      <mass value="1.993"/>
      <inertia ixx="0.002446735" ixy="-0.00059805" ixz="-1.945e-06" iyy="0.003925876" iyz="-1.284e-06" izz="0.004148145"/>
    </inertial>
  </link>
  <link name="RR_hip_rotor">
    <visual>
      <origin rpy="0 1.5707963267948966 0" xyz="0 0 0"/>
      <geometry>
        <cylinder length="0.02" radius="0.035"/>
      </geometry>
      <material name="green"/>
    </visual>
    <!-- <collision>
                <origin rpy="0 ${PI/2.0} 0" xyz="0 0 0"/>
                <geometry>
                    <cylinder length="0.02" radius="0.035"/>
                </geometry>
            </collision> -->
    <inertial>
      <origin rpy="0 0 0" xyz="0.0 0.0 0.0"/>
      <mass value="0.146"/>
      <inertia ixx="0.000138702" ixy="0.0" ixz="0.0" iyy="8.3352e-05" iyz="0.0" izz="8.3352e-05"/>
    </inertial>
  </link>
  <joint name="RR_thigh_joint" type="revolute">
    <origin rpy="0 0 0" xyz="0 -0.0868 0"/>
    <parent link="RR_hip"/>
    <child link="RR_thigh"/>
    <axis xyz="0 1 0"/>
    <dynamics damping="0" friction="0"/>
    <limit effort="35.278" lower="-0.524" upper="3.927" velocity="20"/>
  </joint>
  <joint name="RR_thigh_rotor_joint" type="fixed">
    <origin rpy="0 0 0" xyz="0.0 -0.0298 0"/>
    <parent link="RR_hip"/>
    <child link="RR_thigh_rotor"/>
  </joint>
  <link name="RR_thigh">
    <visual>
      <origin rpy="0 0 0" xyz="0 0 0"/>
      <geometry>
        <mesh filename="resources/robots/aliengo_description/meshes/thigh_mirror.dae" scale="1 1 1"/>
      </geometry>
      <material name="brown"/>
    </visual>
    <collision>
      <origin rpy="0 1.5707963267948966 0" xyz="0 0 -0.125"/>
      <geometry>
        <box size="0.25 0.0374 0.043"/>
      </geometry>
    </collision>
    <inertial>
      <origin rpy="0 0 0" xyz="-0.005607 0.003877 -0.048199"/>
      <mass value="0.639"/>
      <inertia ixx="0.004173855" ixy="-1.0284e-05" ixz="-0.000318874" iyy="0.004343802" iyz="-0.000109233" izz="0.000340136"/>
    </inertial>
  </link>
  <link name="RR_thigh_rotor">
    <visual>
      <origin rpy="1.5707963267948966 0 0" xyz="0 0 0"/>
      <geometry>
        <cylinder length="0.02" radius="0.035"/>
      </geometry>
      <material name="green"/>
    </visual>
    <!-- <collision>
                <origin rpy="${PI/2.0} 0 0" xyz="0 0 0"/>
                <geometry>
                    <cylinder length="0.02" radius="0.035"/>
                </geometry>
            </collision> -->
    <inertial>
      <origin rpy="0 0 0" xyz="0.0 0.0 0.0"/>
      <mass value="0.146"/>
      <inertia ixx="8.3352e-05" ixy="0.0" ixz="0.0" iyy="0.000138702" iyz="0.0" izz="8.3352e-05"/>
    </inertial>
  </link>
  <joint name="RR_calf_joint" type="revolute">
    <origin rpy="0 0 0" xyz="0 0 -0.25"/>
    <parent link="RR_thigh"/>
    <child link="RR_calf"/>
    <axis xyz="0 1 0"/>
    <dynamics damping="0" friction="0"/>
    <limit effort="44.4" lower="-2.775073510670984" upper="-0.6457718232379019" velocity="15.89"/>
  </joint>
  <joint name="RR_calf_rotor_joint" type="fixed">
    <origin rpy="0 0 0" xyz="0.0 0.0997 0"/>
    <parent link="RR_thigh"/>
    <child link="RR_calf_rotor"/>
  </joint>
  <link name="RR_calf">
    <visual>
      <origin rpy="0 0 0" xyz="0 0 0"/>
      <geometry>
        <mesh filename="resources/robots/aliengo_description/meshes/calf.dae" scale="1 1 1"/>
      </geometry>
      <material name="brown"/>
    </visual>
    <collision>
      <origin rpy="0 1.5707963267948966 0" xyz="0 0 -0.125"/>
      <geometry>
        <box size="0.25 0.0208 0.016"/>
      </geometry>
    </collision>
    <inertial>
      <origin rpy="0 0 0" xyz="0.002781 6.3e-05 -0.142518"/>
      <mass value="0.207"/>
      <inertia ixx="0.002129279" ixy="3.9e-08" ixz="5.757e-06" iyy="0.002141463" iyz="-5.16e-07" izz="3.7583e-05"/>
    </inertial>
  </link>
  <link name="RR_calf_rotor">
    <visual>
      <origin rpy="1.5707963267948966 0 0" xyz="0 0 0"/>
      <geometry>
        <cylinder length="0.02" radius="0.035"/>
      </geometry>
      <material name="green"/>
    </visual>
    <!-- <collision>
                <origin rpy="${PI/2.0} 0 0" xyz="0 0 0"/>
                <geometry>
                    <cylinder length="0.02" radius="0.035"/>
                </geometry>
            </collision> -->
    <inertial>
      <origin rpy="0 0 0" xyz="0.0 0.0 0.0"/>
      <mass value="0.132"/>
      <inertia ixx="0.000145463" ixy="0.0" ixz="0.0" iyy="0.000133031" iyz="0.0" izz="0.000145463"/>
    </inertial>
  </link>
  <joint name="RR_foot_fixed" type="fixed" dont_collapse="true">
    <origin rpy="0 0 0" xyz="0 0 -0.25"/>
    <parent link="RR_calf"/>
    <child link="RR_foot"/>
  </joint>
  <link name="RR_foot">
    <visual>
      <origin rpy="0 0 0" xyz="0 0 0"/>
      <geometry>
        <sphere radius="0.0165"/>
      </geometry>
      <material name="green"/>
    </visual>
    <collision>
      <origin rpy="0 0 0" xyz="0 0 0"/>
      <geometry>
        <sphere radius="0.0265"/>
      </geometry>
    </collision>
    <inertial>
      <mass value="0.06"/>
      <inertia ixx="1.6853999999999998e-05" ixy="0.0" ixz="0.0" iyy="1.6853999999999998e-05" iyz="0.0" izz="1.6853999999999998e-05"/>
    </inertial>
  </link>
  <transmission name="RR_hip_tran">
    <type>transmission_interface/SimpleTransmission</type>
    <joint name="RR_hip_joint">
      <hardwareInterface>hardware_interface/EffortJointInterface</hardwareInterface>
    </joint>
    <actuator name="RR_hip_motor">
      <hardwareInterface>hardware_interface/EffortJointInterface</hardwareInterface>
      <mechanicalReduction>1</mechanicalReduction>
    </actuator>
  </transmission>
  <transmission name="RR_thigh_tran">
    <type>transmission_interface/SimpleTransmission</type>
    <joint name="RR_thigh_joint">
      <hardwareInterface>hardware_interface/EffortJointInterface</hardwareInterface>
    </joint>
    <actuator name="RR_thigh_motor">
      <hardwareInterface>hardware_interface/EffortJointInterface</hardwareInterface>
      <mechanicalReduction>1</mechanicalReduction>
    </actuator>
  </transmission>
  <transmission name="RR_calf_tran">
    <type>transmission_interface/SimpleTransmission</type>
    <joint name="RR_calf_joint">
      <hardwareInterface>hardware_interface/EffortJointInterface</hardwareInterface>
    </joint>
    <actuator name="RR_calf_motor">
      <hardwareInterface>hardware_interface/EffortJointInterface</hardwareInterface>
      <mechanicalReduction>1</mechanicalReduction>
    </actuator>
  </transmission>
  <joint name="RL_hip_joint" type="revolute">
    <origin rpy="0 0 0" xyz="-0.2407 0.051 0"/>
    <parent link="trunk"/>
    <child link="RL_hip"/>
    <axis xyz="1 0 0"/>
    <dynamics damping="0" friction="0"/>
    <limit effort="35.278" lower="-1.2217304763960306" upper="1.2217304763960306" velocity="20"/>
  </joint>
  <joint name="RL_hip_rotor_joint" type="fixed">
    <origin rpy="0 0 0" xyz="-0.139985 0.051 0"/>
    <parent link="trunk"/>
    <child link="RL_hip_rotor"/>
  </joint>
  <link name="RL_hip">
    <visual>
      <origin rpy="0 3.141592653589793 0" xyz="0 0 0"/>
      <geometry>
        <mesh filename="resources/robots/aliengo_description/meshes/hip.dae" scale="1 1 1"/>
      </geometry>
      <material name="brown"/>
    </visual>
    <collision>
      <origin rpy="1.5707963267948966 0 0" xyz="0 0.083 0"/>
      <geometry>
        <cylinder length="0.0418" radius="0.046"/>
      </geometry>
    </collision>
    <inertial>
      <origin rpy="0 0 0" xyz="0.022191 0.015144 -1.5e-05"/>
      <mass value="1.993"/>
      <inertia ixx="0.002446735" ixy="0.00059805" ixz="-1.945e-06" iyy="0.003925876" iyz="1.284e-06" izz="0.004148145"/>
    </inertial>
  </link>
  <link name="RL_hip_rotor">
    <visual>
      <origin rpy="0 1.5707963267948966 0" xyz="0 0 0"/>
      <geometry>
        <cylinder length="0.02" radius="0.035"/>
      </geometry>
      <material name="green"/>
    </visual>
    <!-- <collision>
                <origin rpy="0 ${PI/2.0} 0" xyz="0 0 0"/>
                <geometry>
                    <cylinder length="0.02" radius="0.035"/>
                </geometry>
            </collision> -->
    <inertial>
      <origin rpy="0 0 0" xyz="0.0 0.0 0.0"/>
      <mass value="0.146"/>
      <inertia ixx="0.000138702" ixy="0.0" ixz="0.0" iyy="8.3352e-05" iyz="0.0" izz="8.3352e-05"/>
    </inertial>
  </link>
  <joint name="RL_thigh_joint" type="revolute">
    <origin rpy="0 0 0" xyz="0 0.0868 0"/>
    <parent link="RL_hip"/>
    <child link="RL_thigh"/>
    <axis xyz="0 1 0"/>
    <dynamics damping="0" friction="0"/>
    <limit effort="35.278"  lower="-0.524" upper="3.927" velocity="20"/>
  </joint>
  <joint name="RL_thigh_rotor_joint" type="fixed">
    <origin rpy="0 0 0" xyz="0.0 0.0298 0"/>
    <parent link="RL_hip"/>
    <child link="RL_thigh_rotor"/>
  </joint>
  <link name="RL_thigh">
    <visual>
      <origin rpy="0 0 0" xyz="0 0 0"/>
      <geometry>
        <mesh filename="resources/robots/aliengo_description/meshes/thigh.dae" scale="1 1 1"/>
      </geometry>
      <material name="brown"/>
    </visual>
    <collision>
      <origin rpy="0 1.5707963267948966 0" xyz="0 0 -0.125"/>
      <geometry>
        <box size="0.25 0.0374 0.043"/>
      </geometry>
    </collision>
    <inertial>
      <origin rpy="0 0 0" xyz="-0.005607 -0.003877 -0.048199"/>
      <mass value="0.639"/>
      <inertia ixx="0.004173855" ixy="1.0284e-05" ixz="-0.000318874" iyy="0.004343802" iyz="0.000109233" izz="0.000340136"/>
    </inertial>
  </link>
  <link name="RL_thigh_rotor">
    <visual>
      <origin rpy="1.5707963267948966 0 0" xyz="0 0 0"/>
      <geometry>
        <cylinder length="0.02" radius="0.035"/>
      </geometry>
      <material name="green"/>
    </visual>
    <!-- <collision>
                <origin rpy="${PI/2.0} 0 0" xyz="0 0 0"/>
                <geometry>
                    <cylinder length="0.02" radius="0.035"/>
                </geometry>
            </collision> -->
    <inertial>
      <origin rpy="0 0 0" xyz="0.0 0.0 0.0"/>
      <mass value="0.146"/>
      <inertia ixx="8.3352e-05" ixy="0.0" ixz="0.0" iyy="0.000138702" iyz="0.0" izz="8.3352e-05"/>
    </inertial>
  </link>
  <joint name="RL_calf_joint" type="revolute">
    <origin rpy="0 0 0" xyz="0 0 -0.25"/>
    <parent link="RL_thigh"/>
    <child link="RL_calf"/>
    <axis xyz="0 1 0"/>
    <dynamics damping="0" friction="0"/>
    <limit effort="44.4" lower="-2.775073510670984" upper="-0.6457718232379019" velocity="15.89"/>
  </joint>
  <joint name="RL_calf_rotor_joint" type="fixed">
    <origin rpy="0 0 0" xyz="0.0 -0.0997 0"/>
    <parent link="RL_thigh"/>
    <child link="RL_calf_rotor"/>
  </joint>
  <link name="RL_calf">
    <visual>
      <origin rpy="0 0 0" xyz="0 0 0"/>
      <geometry>
        <mesh filename="resources/robots/aliengo_description/meshes/calf.dae" scale="1 1 1"/>
      </geometry>
      <material name="brown"/>
    </visual>
    <collision>
      <origin rpy="0 1.5707963267948966 0" xyz="0 0 -0.125"/>
      <geometry>
        <box size="0.25 0.0208 0.016"/>
      </geometry>
    </collision>
    <inertial>
      <origin rpy="0 0 0" xyz="0.002781 6.3e-05 -0.142518"/>
      <mass value="0.207"/>
      <inertia ixx="0.002129279" ixy="3.9e-08" ixz="5.757e-06" iyy="0.002141463" iyz="-5.16e-07" izz="3.7583e-05"/>
    </inertial>
  </link>
  <link name="RL_calf_rotor">
    <visual>
      <origin rpy="1.5707963267948966 0 0" xyz="0 0 0"/>
      <geometry>
        <cylinder length="0.02" radius="0.035"/>
      </geometry>
      <material name="green"/>
    </visual>
    <!-- <collision>
                <origin rpy="${PI/2.0} 0 0" xyz="0 0 0"/>
                <geometry>
                    <cylinder length="0.02" radius="0.035"/>
                </geometry>
            </collision> -->
    <inertial>
      <origin rpy="0 0 0" xyz="0.0 0.0 0.0"/>
      <mass value="0.132"/>
      <inertia ixx="0.000145463" ixy="0.0" ixz="0.0" iyy="0.000133031" iyz="0.0" izz="0.000145463"/>
    </inertial>
  </link>
  <joint name="RL_foot_fixed" type="fixed" dont_collapse="true">
    <origin rpy="0 0 0" xyz="0 0 -0.25"/>
    <parent link="RL_calf"/>
    <child link="RL_foot"/>
  </joint>
  <link name="RL_foot">
    <visual>
      <origin rpy="0 0 0" xyz="0 0 0"/>
      <geometry>
        <sphere radius="0.0165"/>
      </geometry>
      <material name="green"/>
    </visual>
    <collision>
      <origin rpy="0 0 0" xyz="0 0 0"/>
      <geometry>
        <sphere radius="0.0265"/>
      </geometry>
    </collision>
    <inertial>
      <mass value="0.06"/>
      <inertia ixx="1.6853999999999998e-05" ixy="0.0" ixz="0.0" iyy="1.6853999999999998e-05" iyz="0.0" izz="1.6853999999999998e-05"/>
    </inertial>
  </link>


  <joint name="FR_foot_target_joint"
      type="fixed" dont_collapse="true">
      <origin xyz="0.35 -0.20 0" rpy="0 0 0" />
      <parent link="base" />
      <child link="FR_foot_target" />
  </joint>
  <link name="FR_foot_target">
  </link>
  <joint name="FL_foot_target_joint"
      type="fixed" dont_collapse="true">
      <origin xyz="0.35 0.20 0" rpy="0 0 0" />
      <parent link="base" />
      <child link="FL_foot_target" />
  </joint>
  <link name="FL_foot_target">
  </link>
  <joint name="RR_foot_target_joint"
      type="fixed" dont_collapse="true">
      <origin xyz="-0.20 -0.20 0" rpy="0 0 0" />
      <parent link="base" />
      <child link="RR_foot_target" />
  </joint>
  <link name="RR_foot_target">
  </link>
  <joint name="RL_foot_target_joint"
      type="fixed" dont_collapse="true">
      <origin xyz="-0.20 0.20 0" rpy="0 0 0" />
      <parent link="base" />
      <child link="RL_foot_target" />
  </joint>
  <link name="RL_foot_target">
  </link>

</robot>

